Workbook

Sheet Raw Data
A1: Patient ID | B1: Age | C1: Gender | D1: Disease | E1: Medication | F1: Dosage (mg)
A2: 1 | B2: 8 | C2: Female | D2: Hypertension | E2: Amlodipine | F2: 5
A3: 2 | B3: 33 | C3: Male | D3: Asthma | E3: Salbutamol | F3: 100
A4: 3 | B4: 74 | C4: Male | D4: Hypertension | E4: Amlodipine | F4: 5
A5: 4 | B5: 9 | C5: Male | D5: Allergy | E5: Cetirizine | F5: 10
A6: 5 | C6: Male | D6: Hypertension | E6: Amlodipine | F6: 5
A7: 6 | B7: 76 | C7: female | D7: Flu | E7: Paracetamol | F7: 500
A8: 7 | B8: 33 | C8: Female | D8: Allergy | E8: Cetirizine | F8: 10
A9: 8 | B9: 5 | C9: Male | D9: Arthritis | E9: Ibuprofen | F9: 400
A10: 9 | B10: 48 | C10: Female | E10: Cetirizine | F10: 10
A11: 10 | B11: 32 | C11: MALE | D11: Diabetes | E11: Metformin | F11: 500
A12: 11 | B12: 16 | C12: Female | D12: Hypertension | E12: Amlodipine | F12: 5
A13: 12 | B13: 50 | C13: Female | D13: Hypertension | E13: Amlodipine | F13: 5
A14: 13 | B14: 10 | C14: F | D14: Arthritis | E14: Ibuprofen | F14: 400
A15: 14 | B15: 53 | C15: Male | D15: Hypertension | E15: Amlodipine
A16: 15 | B16: 85 | C16: Female | D16: Arthritis | E16: Ibuprofen | F16: 400
A17: 16 | B17: 13 | D17: flu | E17: Salbutamol | F17: 100
A18: 17 | B18: 42 | C18: Male | D18: Asthma | E18: Salbutamol | F18: 100
A19: 18 | B19: 17 | D19: Asthma | E19: Salbutamol | F19: 100
A20: 19 | B20: 63 | C20: Female | D20: Arthritis | E20: Ibuprofen | F20: 400
A21: 20 | B21: 52 | C21: Female | D21: Diabetes | E21: Metformin | F21: 500
A22: 21 | B22: 39 | C22: Male | D22: DIABETES | E22: Salbutamol | F22: 100
A23: 22 | C23: Male | D23: Diabetes | E23: Metformin | F23: 500
A24: 23 | B24: 64 | C24: Female | D24: Diabetes | E24: Metformin | F24: 500
A25: 24 | B25: 76 | C25: Male | D25: Arthritis | E25: Ibuprofen | F25: 400
A26: 25 | B26: 12 | C26: Male | D26: Migraine | E26: Sumatriptan | F26: 50
A27: 26 | B27: 45 | C27: Female | D27: Flu | E27: paracetamol | F27: 500
A28: 27 | B28: 13 | C28: Male | D28: Arthritis | E28: Ibuprofen | F28: 400
A29: 28 | B29: 32 | C29: Female | D29: Migraine | E29: Sumatriptan | F29: 50
A30: 29 | B30: 63 | C30: Male | D30: Allergy | E30: Cetirizine | F30: 10
A31: 30 | B31: 22 | C31: Male | D31: Arthritis | E31: Ibuprofen | F31: 400
A32: 31 | B32: 250 | C32: Female | D32: Arthritis | E32: Ibuprofen | F32: 400
A33: 32 | B33: 51 | C33: Male | D33: Allergy | E33: Cetirizine
A34: 33 | C34: Female | D34: Diabetes | E34: Metformin | F34: 500
A35: 34 | B35: 11 | C35: Male | D35: Hypertension | E35: Amlodipine | F35: 5
A36: 35 | B36: 85 | C36: Male | D36: Diabetes | E36: Metformin
A37: 36 | B37: 81 | C37: Male | D37: Allergy | E37: Cetirizine | F37: 10
A38: 37 | B38: 53 | C38: Female | D38: Allergy | E38: Cetirizine | F38: 10
A39: 38 | B39: 75 | C39: Male | D39: Arthritis | E39: Ibuprofen | F39: 400
A40: 39 | B40: 73 | C40: Female | D40: Hypertension | E40: Amlodipine | F40: 5
...

Sheet Column Types
A1: Identifying Column Types
A3: Column | B3: Type | C3: Data Kind | D3: Example | E3: Non-blank (raw) | F3: Unique values (raw)
A4: Patient ID | B4: Identifier | C4: Numeric (unique key) | D4: ='Raw Data'!A2 -> 1 | E4: =COUNTA('Raw Data'!A2:A66) -> 65 | F4: =SUMPRODUCT(('Raw Data'!A2:A66<>"")/COUNTIF('Raw Data'!A2:A66,'Raw Data'!A2:A66&"")) -> 60
A5: Age | B5: Numerical | C5: Discrete, in years | D5: ='Raw Data'!B2 -> 8 | E5: =COUNTA('Raw Data'!B2:B66) -> 61 | F5: =SUMPRODUCT(('Raw Data'!B2:B66<>"")/COUNTIF('Raw Data'!B2:B66,'Raw Data'!B2:B66&"")) -> 41
A6: Gender | B6: Categorical | C6: Nominal (Male/Female) | D6: ='Raw Data'!C2 -> Female | E6: =COUNTA('Raw Data'!C2:C66) -> 62 | F6: =SUMPRODUCT(('Raw Data'!C2:C66<>"")/COUNTIF('Raw Data'!C2:C66,'Raw Data'!C2:C66&"")) -> 4
A7: Disease | B7: Categorical | C7: Nominal | D7: ='Raw Data'!D2 -> Hypertension | E7: =COUNTA('Raw Data'!D2:D66) -> 63 | F7: =SUMPRODUCT(('Raw Data'!D2:D66<>"")/COUNTIF('Raw Data'!D2:D66,'Raw Data'!D2:D66&"")) -> 9
A8: Medication | B8: Categorical | C8: Nominal | D8: ='Raw Data'!E2 -> Amlodipine | E8: =COUNTA('Raw Data'!E2:E66) -> 65 | F8: =SUMPRODUCT(('Raw Data'!E2:E66<>"")/COUNTIF('Raw Data'!E2:E66,'Raw Data'!E2:E66&"")) -> 9
A9: Dosage (mg) | B9: Numerical | C9: Continuous, in mg | D9: ='Raw Data'!F2 -> 5 | E9: =COUNTA('Raw Data'!F2:F66) -> 62 | F9: =SUMPRODUCT(('Raw Data'!F2:F66<>"")/COUNTIF('Raw Data'!F2:F66,'Raw Data'!F2:F66&"")) -> 6

Sheet Data Quality
A1: Data Quality Check (on Raw Data)
A3: Check | B3: Result
A4: Total records | B4: =COUNTA('Raw Data'!A2:A66) -> 65
A5: Missing Age | B5: =COUNTBLANK('Raw Data'!B2:B66) -> 4
A6: Missing Gender | B6: =COUNTBLANK('Raw Data'!C2:C66) -> 3
A7: Missing Disease | B7: =COUNTBLANK('Raw Data'!D2:D66) -> 2
A8: Missing Medication | B8: =COUNTBLANK('Raw Data'!E2:E66) -> 0
A9: Missing Dosage | B9: =COUNTBLANK('Raw Data'!F2:F66) -> 3
A10: Duplicate records (repeat Patient IDs) | B10: =B4-SUMPRODUCT(1/COUNTIF('Raw Data'!A2:A66,'Raw Data'!A2:A66)) -> 5
A11: Invalid ages (<0 or >120) | B11: =COUNTIF('Raw Data'!B2:B66,">120")+COUNTIF('Raw Data'!B2:B66,"<0") -> 1
A13: Also: Gender/Disease/Medication contain extra spaces and mixed case (e.g. ' female ', 'MALE', 'F', 'DIABETES').

Sheet Cleaning Steps
A1: Cleaning Steps (how to do each in Excel)
A3: # | B3: Problem | C3: Fix | D3: Excel feature
A4: 1 | B4: Duplicate rows | C4: Remove exact duplicate records | D4: Data > Remove Duplicates (select all columns)
A5: 2 | B5: Extra spaces / mixed case | C5: Trim spaces and use Proper case | D5: Use formula PROPER(TRIM(C2)), then Paste Special > Values
A6: 3 | B6: Gender 'F' / 'M' | C6: Replace with Female / Male | D6: Ctrl+H (Find & Replace) - Match entire cell contents
A7: 4 | B7: Impossible age (250) | C7: Treat as missing, then fill | D7: Filter Age > 120
A8: 5 | B8: Missing Age | C8: Fill with median age = 48 | D8: Use formula MEDIAN(range), then type it into blanks
A9: 6 | B9: Missing Dosage | C9: Fill with that medication's usual dose | D9: Filter blanks; copy dose from same Medication
A10: 7 | B10: Missing Gender / Disease | C10: Delete the row (cannot be guessed) | D10: Filter blanks > Delete Row
A12: Assumption: median age 48 was calculated from valid ages after removing duplicates.

Sheet Cleaned Data
A1: Patient ID | B1: Age | C1: Gender | D1: Disease | E1: Medication | F1: Dosage (mg)
A2: 1 | B2: 8 | C2: Female | D2: Hypertension | E2: Amlodipine | F2: 5
A3: 2 | B3: 33 | C3: Male | D3: Asthma | E3: Salbutamol | F3: 100
A4: 3 | B4: 74 | C4: Male | D4: Hypertension | E4: Amlodipine | F4: 5
A5: 4 | B5: 9 | C5: Male | D5: Allergy | E5: Cetirizine | F5: 10
A6: 5 | B6: 48 | C6: Male | D6: Hypertension | E6: Amlodipine | F6: 5
A7: 6 | B7: 76 | C7: Female | D7: Flu | E7: Paracetamol | F7: 500
A8: 7 | B8: 33 | C8: Female | D8: Allergy | E8: Cetirizine | F8: 10
A9: 8 | B9: 5 | C9: Male | D9: Arthritis | E9: Ibuprofen | F9: 400
A10: 10 | B10: 32 | C10: Male | D10: Diabetes | E10: Metformin | F10: 500
A11: 11 | B11: 16 | C11: Female | D11: Hypertension | E11: Amlodipine | F11: 5
A12: 12 | B12: 50 | C12: Female | D12: Hypertension | E12: Amlodipine | F12: 5
A13: 13 | B13: 10 | C13: Female | D13: Arthritis | E13: Ibuprofen | F13: 400
... A56: 60 | B56: 13 | C56: Male | D56: Asthma | E56: Salbutamol | F56: 100

Sheet Analysis
A1: Basic Analysis (on Cleaned Data)
A3: Metric | B3: Value
A4: Total patients | B4: =COUNTA('Cleaned Data'!$A$2:$A$56) -> 55
A5: Average age | B5: =AVERAGE('Cleaned Data'!$B$2:$B$56) -> 45.745455
A6: Youngest patient | B6: =MIN('Cleaned Data'!$B$2:$B$56) -> 5
A7: Oldest patient | B7: =MAX('Cleaned Data'!$B$2:$B$56) -> 85
A8: Male patients | B8: =COUNTIF('Cleaned Data'!$C$2:$C$56,"Male") -> 32
A9: Female patients | B9: =COUNTIF('Cleaned Data'!$C$2:$C$56,"Female") -> 23
A12: Disease | B12: Patient Count | C12: % of Patients | D12: Average Age
A13: Hypertension | B13: =COUNTIF('Cleaned Data'!$D$2:$D$56,A13) -> 12 | C13: =B13/$B$4 -> 0.21818182 | D13: =AVERAGEIF('Cleaned Data'!$D$2:$D$56,A13,'Cleaned Data'!$B$2:$B$56) -> 43.083333
A14: Arthritis | B14: =COUNTIF('Cleaned Data'!$D$2:$D$56,A14) -> 11 | C14: =B14/$B$4 -> 0.2 | D14: =AVERAGEIF('Cleaned Data'!$D$2:$D$56,A14,'Cleaned Data'!$B$2:$B$56) -> 47.727273
A15: Diabetes | B15: =COUNTIF('Cleaned Data'!$D$2:$D$56,A15) -> 9 | C15: =B15/$B$4 -> 0.16363636 | D15: =AVERAGEIF('Cleaned Data'!$D$2:$D$56,A15,'Cleaned Data'!$B$2:$B$56) -> 56.333333
A16: Asthma | B16: =COUNTIF('Cleaned Data'!$D$2:$D$56,A16) -> 7 | C16: =B16/$B$4 -> 0.12727273 | D16: =AVERAGEIF('Cleaned Data'!$D$2:$D$56,A16,'Cleaned Data'!$B$2:$B$56) -> 39.714286
A17: Allergy | B17: =COUNTIF('Cleaned Data'!$D$2:$D$56,A17) -> 7 | C17: =B17/$B$4 -> 0.12727273 | D17: =AVERAGEIF('Cleaned Data'!$D$2:$D$56,A17,'Cleaned Data'!$B$2:$B$56) -> 45
A18: Flu | B18: =COUNTIF('Cleaned Data'!$D$2:$D$56,A18) -> 4 | C18: =B18/$B$4 -> 0.072727273 | D18: =AVERAGEIF('Cleaned Data'!$D$2:$D$56,A18,'Cleaned Data'!$B$2:$B$56) -> 43.25
A19: Migraine | B19: =COUNTIF('Cleaned Data'!$D$2:$D$56,A19) -> 4 | C19: =B19/$B$4 -> 0.072727273 | D19: =AVERAGEIF('Cleaned Data'!$D$2:$D$56,A19,'Cleaned Data'!$B$2:$B$56) -> 32.5
A20: Infection | B20: =COUNTIF('Cleaned Data'!$D$2:$D$56,A20) -> 1 | C20: =B20/$B$4 -> 0.018181818 | D20: =AVERAGEIF('Cleaned Data'!$D$2:$D$56,A20,'Cleaned Data'!$B$2:$B$56) -> 71
A21: Total | B21: =SUM(B13:B20) -> 55
A23: Most common disease | B23: =INDEX(A13:A20,MATCH(MAX(B13:B20),B13:B20,0)) -> Hypertension
A26: Medication | B26: Patients | C26: Average Dosage (mg)
A27: Amlodipine | B27: =COUNTIF('Cleaned Data'!$E$2:$E$56,A27) -> 12 | C27: =AVERAGEIF('Cleaned Data'!$E$2:$E$56,A27,'Cleaned Data'!$F$2:$F$56) -> 5
A28: Ibuprofen | B28: =COUNTIF('Cleaned Data'!$E$2:$E$56,A28) -> 11 | C28: =AVERAGEIF('Cleaned Data'!$E$2:$E$56,A28,'Cleaned Data'!$F$2:$F$56) -> 400
A29: Salbutamol | B29: =COUNTIF('Cleaned Data'!$E$2:$E$56,A29) -> 8 | C29: =AVERAGEIF('Cleaned Data'!$E$2:$E$56,A29,'Cleaned Data'!$F$2:$F$56) -> 100
A30: Metformin | B30: =COUNTIF('Cleaned Data'!$E$2:$E$56,A30) -> 8 | C30: =AVERAGEIF('Cleaned Data'!$E$2:$E$56,A30,'Cleaned Data'!$F$2:$F$56) -> 500
A31: Cetirizine | B31: =COUNTIF('Cleaned Data'!$E$2:$E$56,A31) -> 7 | C31: =AVERAGEIF('Cleaned Data'!$E$2:$E$56,A31,'Cleaned Data'!$F$2:$F$56) -> 10
A32: Paracetamol | B32: =COUNTIF('Cleaned Data'!$E$2:$E$56,A32) -> 4 | C32: =AVERAGEIF('Cleaned Data'!$E$2:$E$56,A32,'Cleaned Data'!$F$2:$F$56) -> 500
A33: Sumatriptan | B33: =COUNTIF('Cleaned Data'!$E$2:$E$56,A33) -> 4 | C33: =AVERAGEIF('Cleaned Data'!$E$2:$E$56,A33,'Cleaned Data'!$F$2:$F$56) -> 50
A34: Amoxicillin | B34: =COUNTIF('Cleaned Data'!$E$2:$E$56,A34) -> 1 | C34: =AVERAGEIF('Cleaned Data'!$E$2:$E$56,A34,'Cleaned Data'!$F$2:$F$56) -> 500
